[2023-10-22T22:00:15.033+0300] {taskinstance.py:1157} INFO - Dependencies all met for dep_context=non-requeueable deps ti=<TaskInstance: dm1trybu.train_lr scheduled__2023-10-21T09:45:00+00:00 [queued]>
[2023-10-22T22:00:15.039+0300] {taskinstance.py:1157} INFO - Dependencies all met for dep_context=requeueable deps ti=<TaskInstance: dm1trybu.train_lr scheduled__2023-10-21T09:45:00+00:00 [queued]>
[2023-10-22T22:00:15.039+0300] {taskinstance.py:1359} INFO - Starting attempt 6 of 8
[2023-10-22T22:00:15.050+0300] {taskinstance.py:1380} INFO - Executing <Task(PythonOperator): train_lr> on 2023-10-21 09:45:00+00:00
[2023-10-22T22:00:15.064+0300] {standard_task_runner.py:57} INFO - Started process 226532 to run task
[2023-10-22T22:00:15.074+0300] {standard_task_runner.py:84} INFO - Running: ['airflow', 'tasks', 'run', 'dm1trybu', 'train_lr', 'scheduled__2023-10-21T09:45:00+00:00', '--job-id', '148', '--raw', '--subdir', 'DAGS_FOLDER/final_dag_3_models.py', '--cfg-path', '/tmp/tmpl8c0lglm']
[2023-10-22T22:00:15.077+0300] {standard_task_runner.py:85} INFO - Job 148: Subtask train_lr
[2023-10-22T22:00:15.141+0300] {task_command.py:415} INFO - Running <TaskInstance: dm1trybu.train_lr scheduled__2023-10-21T09:45:00+00:00 [running]> on host dsbulgako1-QEMU-Virtual-Machine
[2023-10-22T22:00:15.231+0300] {taskinstance.py:1660} INFO - Exporting env vars: AIRFLOW_CTX_DAG_EMAIL='dmitrii.bulghakov@bk.ru' AIRFLOW_CTX_DAG_OWNER='Dmitry Bulgakov' AIRFLOW_CTX_DAG_ID='dm1trybu' AIRFLOW_CTX_TASK_ID='train_lr' AIRFLOW_CTX_EXECUTION_DATE='2023-10-21T09:45:00+00:00' AIRFLOW_CTX_TRY_NUMBER='6' AIRFLOW_CTX_DAG_RUN_ID='scheduled__2023-10-21T09:45:00+00:00'
[2023-10-22T22:00:15.249+0300] {s3.py:1359} INFO - This function shadows the 'download_file' method of S3 API, but it is not the same. If you want to use the original method from S3 API, please call 'S3Hook.get_conn().download_file()'
[2023-10-22T22:00:15.249+0300] {s3.py:1365} INFO - Downloading source S3 file from Bucket mlops-project with path dm1trybu/datasets/X_train.pkl
[2023-10-22T22:00:15.261+0300] {base_aws.py:553} WARNING - Unable to find AWS Connection ID 's3_connection', switching to empty.
[2023-10-22T22:00:15.261+0300] {base_aws.py:161} INFO - No connection ID provided. Fallback on boto3 credential strategy (region_name=None). See: https://boto3.amazonaws.com/v1/documentation/api/latest/guide/configuration.html
[2023-10-22T22:00:15.280+0300] {credentials.py:1254} INFO - Found credentials in shared credentials file: ~/.aws/credentials
[2023-10-22T22:00:15.577+0300] {configprovider.py:949} INFO - Found endpoint for s3 via: config_global.
[2023-10-22T22:00:16.910+0300] {s3.py:1359} INFO - This function shadows the 'download_file' method of S3 API, but it is not the same. If you want to use the original method from S3 API, please call 'S3Hook.get_conn().download_file()'
[2023-10-22T22:00:16.910+0300] {s3.py:1365} INFO - Downloading source S3 file from Bucket mlops-project with path dm1trybu/datasets/X_test.pkl
[2023-10-22T22:00:16.910+0300] {base_aws.py:161} INFO - No connection ID provided. Fallback on boto3 credential strategy (region_name=None). See: https://boto3.amazonaws.com/v1/documentation/api/latest/guide/configuration.html
[2023-10-22T22:00:16.923+0300] {credentials.py:1254} INFO - Found credentials in shared credentials file: ~/.aws/credentials
[2023-10-22T22:00:16.948+0300] {configprovider.py:949} INFO - Found endpoint for s3 via: config_global.
[2023-10-22T22:00:18.973+0300] {s3.py:1359} INFO - This function shadows the 'download_file' method of S3 API, but it is not the same. If you want to use the original method from S3 API, please call 'S3Hook.get_conn().download_file()'
[2023-10-22T22:00:18.973+0300] {s3.py:1365} INFO - Downloading source S3 file from Bucket mlops-project with path dm1trybu/datasets/y_train.pkl
[2023-10-22T22:00:18.973+0300] {base_aws.py:161} INFO - No connection ID provided. Fallback on boto3 credential strategy (region_name=None). See: https://boto3.amazonaws.com/v1/documentation/api/latest/guide/configuration.html
[2023-10-22T22:00:18.985+0300] {credentials.py:1254} INFO - Found credentials in shared credentials file: ~/.aws/credentials
[2023-10-22T22:00:19.009+0300] {configprovider.py:949} INFO - Found endpoint for s3 via: config_global.
[2023-10-22T22:00:20.131+0300] {s3.py:1359} INFO - This function shadows the 'download_file' method of S3 API, but it is not the same. If you want to use the original method from S3 API, please call 'S3Hook.get_conn().download_file()'
[2023-10-22T22:00:20.131+0300] {s3.py:1365} INFO - Downloading source S3 file from Bucket mlops-project with path dm1trybu/datasets/y_test.pkl
[2023-10-22T22:00:20.131+0300] {base_aws.py:161} INFO - No connection ID provided. Fallback on boto3 credential strategy (region_name=None). See: https://boto3.amazonaws.com/v1/documentation/api/latest/guide/configuration.html
[2023-10-22T22:00:20.142+0300] {credentials.py:1254} INFO - Found credentials in shared credentials file: ~/.aws/credentials
[2023-10-22T22:00:20.166+0300] {configprovider.py:949} INFO - Found endpoint for s3 via: config_global.
[2023-10-22T22:00:20.766+0300] {migration.py:213} INFO - Context impl PostgresqlImpl.
[2023-10-22T22:00:20.766+0300] {migration.py:216} INFO - Will assume transactional DDL.
[2023-10-22T22:00:22.177+0300] {logging_mixin.py:151} WARNING - /home/dsbulgako1/my_repos/mlops_project/env/lib/python3.10/site-packages/_distutils_hack/__init__.py:33 UserWarning: Setuptools is replacing distutils.
[2023-10-22T22:00:22.190+0300] {credentials.py:1254} INFO - Found credentials in shared credentials file: ~/.aws/credentials
[2023-10-22T22:00:22.793+0300] {taskinstance.py:1935} ERROR - Task failed with exception
Traceback (most recent call last):
  File "/home/dsbulgako1/my_repos/mlops_project/env/lib/python3.10/site-packages/airflow/operators/python.py", line 192, in execute
    return_value = self.execute_callable()
  File "/home/dsbulgako1/my_repos/mlops_project/env/lib/python3.10/site-packages/airflow/operators/python.py", line 209, in execute_callable
    return self.python_callable(*self.op_args, **self.op_kwargs)
  File "/home/dsbulgako1/my_repos/mlops_project/dags/final_dag_3_models.py", line 236, in train_model
    train_mlflow_model(
  File "/home/dsbulgako1/my_repos/mlops_project/dags/final_dag_3_models.py", line 209, in train_mlflow_model
    mlflow.sklearn.save_model(model, name)
  File "/home/dsbulgako1/my_repos/mlops_project/env/lib/python3.10/site-packages/mlflow/sklearn/__init__.py", line 242, in save_model
    _validate_and_prepare_target_save_path(path)
  File "/home/dsbulgako1/my_repos/mlops_project/env/lib/python3.10/site-packages/mlflow/utils/model_utils.py", line 130, in _validate_and_prepare_target_save_path
    raise MlflowException(
mlflow.exceptions.MlflowException: Path 'lr' already exists and is not empty
[2023-10-22T22:00:22.805+0300] {taskinstance.py:1398} INFO - Marking task as UP_FOR_RETRY. dag_id=dm1trybu, task_id=train_lr, execution_date=20231021T094500, start_date=20231022T190015, end_date=20231022T190022
[2023-10-22T22:00:22.811+0300] {standard_task_runner.py:104} ERROR - Failed to execute job 148 for task train_lr (Path 'lr' already exists and is not empty; 226532)
[2023-10-22T22:00:22.824+0300] {local_task_job_runner.py:228} INFO - Task exited with return code 1
[2023-10-22T22:00:22.840+0300] {taskinstance.py:2776} INFO - 0 downstream tasks scheduled from follow-on schedule check
