[2023-10-22T22:01:24.083+0300] {taskinstance.py:1157} INFO - Dependencies all met for dep_context=non-requeueable deps ti=<TaskInstance: dm1trybu.train_lr scheduled__2023-10-21T09:45:00+00:00 [queued]>
[2023-10-22T22:01:24.087+0300] {taskinstance.py:1157} INFO - Dependencies all met for dep_context=requeueable deps ti=<TaskInstance: dm1trybu.train_lr scheduled__2023-10-21T09:45:00+00:00 [queued]>
[2023-10-22T22:01:24.087+0300] {taskinstance.py:1359} INFO - Starting attempt 7 of 8
[2023-10-22T22:01:24.093+0300] {taskinstance.py:1380} INFO - Executing <Task(PythonOperator): train_lr> on 2023-10-21 09:45:00+00:00
[2023-10-22T22:01:24.097+0300] {standard_task_runner.py:57} INFO - Started process 226922 to run task
[2023-10-22T22:01:24.102+0300] {standard_task_runner.py:84} INFO - Running: ['airflow', 'tasks', 'run', 'dm1trybu', 'train_lr', 'scheduled__2023-10-21T09:45:00+00:00', '--job-id', '151', '--raw', '--subdir', 'DAGS_FOLDER/final_dag_3_models.py', '--cfg-path', '/tmp/tmp7co83xtk']
[2023-10-22T22:01:24.112+0300] {standard_task_runner.py:85} INFO - Job 151: Subtask train_lr
[2023-10-22T22:01:24.168+0300] {task_command.py:415} INFO - Running <TaskInstance: dm1trybu.train_lr scheduled__2023-10-21T09:45:00+00:00 [running]> on host dsbulgako1-QEMU-Virtual-Machine
[2023-10-22T22:01:24.257+0300] {taskinstance.py:1660} INFO - Exporting env vars: AIRFLOW_CTX_DAG_EMAIL='dmitrii.bulghakov@bk.ru' AIRFLOW_CTX_DAG_OWNER='Dmitry Bulgakov' AIRFLOW_CTX_DAG_ID='dm1trybu' AIRFLOW_CTX_TASK_ID='train_lr' AIRFLOW_CTX_EXECUTION_DATE='2023-10-21T09:45:00+00:00' AIRFLOW_CTX_TRY_NUMBER='7' AIRFLOW_CTX_DAG_RUN_ID='scheduled__2023-10-21T09:45:00+00:00'
[2023-10-22T22:01:24.278+0300] {s3.py:1359} INFO - This function shadows the 'download_file' method of S3 API, but it is not the same. If you want to use the original method from S3 API, please call 'S3Hook.get_conn().download_file()'
[2023-10-22T22:01:24.278+0300] {s3.py:1365} INFO - Downloading source S3 file from Bucket mlops-project with path dm1trybu/datasets/X_train.pkl
[2023-10-22T22:01:24.297+0300] {base_aws.py:553} WARNING - Unable to find AWS Connection ID 's3_connection', switching to empty.
[2023-10-22T22:01:24.298+0300] {base_aws.py:161} INFO - No connection ID provided. Fallback on boto3 credential strategy (region_name=None). See: https://boto3.amazonaws.com/v1/documentation/api/latest/guide/configuration.html
[2023-10-22T22:01:24.315+0300] {credentials.py:1254} INFO - Found credentials in shared credentials file: ~/.aws/credentials
[2023-10-22T22:01:24.528+0300] {configprovider.py:949} INFO - Found endpoint for s3 via: config_global.
[2023-10-22T22:03:41.818+0300] {s3.py:1359} INFO - This function shadows the 'download_file' method of S3 API, but it is not the same. If you want to use the original method from S3 API, please call 'S3Hook.get_conn().download_file()'
[2023-10-22T22:03:41.830+0300] {s3.py:1365} INFO - Downloading source S3 file from Bucket mlops-project with path dm1trybu/datasets/X_test.pkl
[2023-10-22T22:03:41.832+0300] {base_aws.py:161} INFO - No connection ID provided. Fallback on boto3 credential strategy (region_name=None). See: https://boto3.amazonaws.com/v1/documentation/api/latest/guide/configuration.html
[2023-10-22T22:03:42.056+0300] {credentials.py:1254} INFO - Found credentials in shared credentials file: ~/.aws/credentials
[2023-10-22T22:03:42.089+0300] {configprovider.py:949} INFO - Found endpoint for s3 via: config_global.
[2023-10-22T22:04:05.980+0300] {s3.py:1359} INFO - This function shadows the 'download_file' method of S3 API, but it is not the same. If you want to use the original method from S3 API, please call 'S3Hook.get_conn().download_file()'
[2023-10-22T22:04:05.981+0300] {s3.py:1365} INFO - Downloading source S3 file from Bucket mlops-project with path dm1trybu/datasets/y_train.pkl
[2023-10-22T22:04:05.982+0300] {base_aws.py:161} INFO - No connection ID provided. Fallback on boto3 credential strategy (region_name=None). See: https://boto3.amazonaws.com/v1/documentation/api/latest/guide/configuration.html
[2023-10-22T22:04:06.184+0300] {credentials.py:1254} INFO - Found credentials in shared credentials file: ~/.aws/credentials
[2023-10-22T22:04:06.268+0300] {configprovider.py:949} INFO - Found endpoint for s3 via: config_global.
[2023-10-22T22:04:07.815+0300] {s3.py:1359} INFO - This function shadows the 'download_file' method of S3 API, but it is not the same. If you want to use the original method from S3 API, please call 'S3Hook.get_conn().download_file()'
[2023-10-22T22:04:07.815+0300] {s3.py:1365} INFO - Downloading source S3 file from Bucket mlops-project with path dm1trybu/datasets/y_test.pkl
[2023-10-22T22:04:07.815+0300] {base_aws.py:161} INFO - No connection ID provided. Fallback on boto3 credential strategy (region_name=None). See: https://boto3.amazonaws.com/v1/documentation/api/latest/guide/configuration.html
[2023-10-22T22:04:07.827+0300] {credentials.py:1254} INFO - Found credentials in shared credentials file: ~/.aws/credentials
[2023-10-22T22:04:07.853+0300] {configprovider.py:949} INFO - Found endpoint for s3 via: config_global.
[2023-10-22T22:04:08.701+0300] {migration.py:213} INFO - Context impl PostgresqlImpl.
[2023-10-22T22:04:08.701+0300] {migration.py:216} INFO - Will assume transactional DDL.
[2023-10-22T22:04:08.731+0300] {taskinstance.py:1935} ERROR - Task failed with exception
Traceback (most recent call last):
  File "/home/dsbulgako1/my_repos/mlops_project/env/lib/python3.10/site-packages/airflow/operators/python.py", line 192, in execute
    return_value = self.execute_callable()
  File "/home/dsbulgako1/my_repos/mlops_project/env/lib/python3.10/site-packages/airflow/operators/python.py", line 209, in execute_callable
    return self.python_callable(*self.op_args, **self.op_kwargs)
  File "/home/dsbulgako1/my_repos/mlops_project/dags/final_dag_3_models.py", line 230, in train_model
    with mlflow.start_run(run_id=metrics["parent_run_id"]):  # parent run
  File "/home/dsbulgako1/my_repos/mlops_project/env/lib/python3.10/site-packages/mlflow/tracking/fluent.py", line 317, in start_run
    raise MlflowException(
mlflow.exceptions.MlflowException: Cannot start run with ID 2ec2ae40d98649ceaa1a74ee5698d37d because it is in the deleted state.
[2023-10-22T22:04:08.744+0300] {taskinstance.py:1398} INFO - Marking task as UP_FOR_RETRY. dag_id=dm1trybu, task_id=train_lr, execution_date=20231021T094500, start_date=20231022T190124, end_date=20231022T190408
[2023-10-22T22:04:08.756+0300] {standard_task_runner.py:104} ERROR - Failed to execute job 151 for task train_lr (Cannot start run with ID 2ec2ae40d98649ceaa1a74ee5698d37d because it is in the deleted state.; 226922)
[2023-10-22T22:04:08.795+0300] {local_task_job_runner.py:228} INFO - Task exited with return code 1
[2023-10-22T22:04:08.817+0300] {taskinstance.py:2776} INFO - 0 downstream tasks scheduled from follow-on schedule check
