[2023-10-22T21:59:00.843+0300] {taskinstance.py:1157} INFO - Dependencies all met for dep_context=non-requeueable deps ti=<TaskInstance: dm1trybu.train_rf scheduled__2023-10-21T09:45:00+00:00 [queued]>
[2023-10-22T21:59:00.848+0300] {taskinstance.py:1157} INFO - Dependencies all met for dep_context=requeueable deps ti=<TaskInstance: dm1trybu.train_rf scheduled__2023-10-21T09:45:00+00:00 [queued]>
[2023-10-22T21:59:00.848+0300] {taskinstance.py:1359} INFO - Starting attempt 5 of 8
[2023-10-22T21:59:00.871+0300] {taskinstance.py:1380} INFO - Executing <Task(PythonOperator): train_rf> on 2023-10-21 09:45:00+00:00
[2023-10-22T21:59:00.878+0300] {standard_task_runner.py:57} INFO - Started process 226091 to run task
[2023-10-22T21:59:00.886+0300] {standard_task_runner.py:84} INFO - Running: ['airflow', 'tasks', 'run', 'dm1trybu', 'train_rf', 'scheduled__2023-10-21T09:45:00+00:00', '--job-id', '144', '--raw', '--subdir', 'DAGS_FOLDER/final_dag_3_models.py', '--cfg-path', '/tmp/tmpa4vxh8_a']
[2023-10-22T21:59:00.889+0300] {standard_task_runner.py:85} INFO - Job 144: Subtask train_rf
[2023-10-22T21:59:00.987+0300] {task_command.py:415} INFO - Running <TaskInstance: dm1trybu.train_rf scheduled__2023-10-21T09:45:00+00:00 [running]> on host dsbulgako1-QEMU-Virtual-Machine
[2023-10-22T21:59:01.146+0300] {taskinstance.py:1660} INFO - Exporting env vars: AIRFLOW_CTX_DAG_EMAIL='dmitrii.bulghakov@bk.ru' AIRFLOW_CTX_DAG_OWNER='Dmitry Bulgakov' AIRFLOW_CTX_DAG_ID='dm1trybu' AIRFLOW_CTX_TASK_ID='train_rf' AIRFLOW_CTX_EXECUTION_DATE='2023-10-21T09:45:00+00:00' AIRFLOW_CTX_TRY_NUMBER='5' AIRFLOW_CTX_DAG_RUN_ID='scheduled__2023-10-21T09:45:00+00:00'
[2023-10-22T21:59:01.172+0300] {s3.py:1359} INFO - This function shadows the 'download_file' method of S3 API, but it is not the same. If you want to use the original method from S3 API, please call 'S3Hook.get_conn().download_file()'
[2023-10-22T21:59:01.172+0300] {s3.py:1365} INFO - Downloading source S3 file from Bucket mlops-project with path dm1trybu/datasets/X_train.pkl
[2023-10-22T21:59:01.192+0300] {base_aws.py:553} WARNING - Unable to find AWS Connection ID 's3_connection', switching to empty.
[2023-10-22T21:59:01.193+0300] {base_aws.py:161} INFO - No connection ID provided. Fallback on boto3 credential strategy (region_name=None). See: https://boto3.amazonaws.com/v1/documentation/api/latest/guide/configuration.html
[2023-10-22T21:59:01.214+0300] {credentials.py:1254} INFO - Found credentials in shared credentials file: ~/.aws/credentials
[2023-10-22T21:59:01.740+0300] {configprovider.py:949} INFO - Found endpoint for s3 via: config_global.
[2023-10-22T21:59:04.730+0300] {s3.py:1359} INFO - This function shadows the 'download_file' method of S3 API, but it is not the same. If you want to use the original method from S3 API, please call 'S3Hook.get_conn().download_file()'
[2023-10-22T21:59:04.730+0300] {s3.py:1365} INFO - Downloading source S3 file from Bucket mlops-project with path dm1trybu/datasets/X_test.pkl
[2023-10-22T21:59:04.731+0300] {base_aws.py:161} INFO - No connection ID provided. Fallback on boto3 credential strategy (region_name=None). See: https://boto3.amazonaws.com/v1/documentation/api/latest/guide/configuration.html
[2023-10-22T21:59:04.742+0300] {credentials.py:1254} INFO - Found credentials in shared credentials file: ~/.aws/credentials
[2023-10-22T21:59:04.771+0300] {configprovider.py:949} INFO - Found endpoint for s3 via: config_global.
[2023-10-22T21:59:05.731+0300] {s3.py:1359} INFO - This function shadows the 'download_file' method of S3 API, but it is not the same. If you want to use the original method from S3 API, please call 'S3Hook.get_conn().download_file()'
[2023-10-22T21:59:05.731+0300] {s3.py:1365} INFO - Downloading source S3 file from Bucket mlops-project with path dm1trybu/datasets/y_train.pkl
[2023-10-22T21:59:05.731+0300] {base_aws.py:161} INFO - No connection ID provided. Fallback on boto3 credential strategy (region_name=None). See: https://boto3.amazonaws.com/v1/documentation/api/latest/guide/configuration.html
[2023-10-22T21:59:05.742+0300] {credentials.py:1254} INFO - Found credentials in shared credentials file: ~/.aws/credentials
[2023-10-22T21:59:05.774+0300] {configprovider.py:949} INFO - Found endpoint for s3 via: config_global.
[2023-10-22T21:59:06.446+0300] {s3.py:1359} INFO - This function shadows the 'download_file' method of S3 API, but it is not the same. If you want to use the original method from S3 API, please call 'S3Hook.get_conn().download_file()'
[2023-10-22T21:59:06.446+0300] {s3.py:1365} INFO - Downloading source S3 file from Bucket mlops-project with path dm1trybu/datasets/y_test.pkl
[2023-10-22T21:59:06.446+0300] {base_aws.py:161} INFO - No connection ID provided. Fallback on boto3 credential strategy (region_name=None). See: https://boto3.amazonaws.com/v1/documentation/api/latest/guide/configuration.html
[2023-10-22T21:59:06.464+0300] {credentials.py:1254} INFO - Found credentials in shared credentials file: ~/.aws/credentials
[2023-10-22T21:59:06.530+0300] {configprovider.py:949} INFO - Found endpoint for s3 via: config_global.
[2023-10-22T21:59:08.256+0300] {migration.py:213} INFO - Context impl PostgresqlImpl.
[2023-10-22T21:59:08.256+0300] {migration.py:216} INFO - Will assume transactional DDL.
[2023-10-22T21:59:19.110+0300] {logging_mixin.py:151} WARNING - /home/dsbulgako1/my_repos/mlops_project/env/lib/python3.10/site-packages/_distutils_hack/__init__.py:33 UserWarning: Setuptools is replacing distutils.
[2023-10-22T21:59:19.124+0300] {credentials.py:1254} INFO - Found credentials in shared credentials file: ~/.aws/credentials
[2023-10-22T21:59:50.501+0300] {taskinstance.py:1935} ERROR - Task failed with exception
Traceback (most recent call last):
  File "/home/dsbulgako1/my_repos/mlops_project/env/lib/python3.10/site-packages/airflow/operators/python.py", line 192, in execute
    return_value = self.execute_callable()
  File "/home/dsbulgako1/my_repos/mlops_project/env/lib/python3.10/site-packages/airflow/operators/python.py", line 209, in execute_callable
    return self.python_callable(*self.op_args, **self.op_kwargs)
  File "/home/dsbulgako1/my_repos/mlops_project/dags/final_dag_3_models.py", line 236, in train_model
    train_mlflow_model(
  File "/home/dsbulgako1/my_repos/mlops_project/dags/final_dag_3_models.py", line 209, in train_mlflow_model
    mlflow.sklearn.save_model(model, name)
  File "/home/dsbulgako1/my_repos/mlops_project/env/lib/python3.10/site-packages/mlflow/sklearn/__init__.py", line 242, in save_model
    _validate_and_prepare_target_save_path(path)
  File "/home/dsbulgako1/my_repos/mlops_project/env/lib/python3.10/site-packages/mlflow/utils/model_utils.py", line 130, in _validate_and_prepare_target_save_path
    raise MlflowException(
mlflow.exceptions.MlflowException: Path 'rf' already exists and is not empty
[2023-10-22T21:59:50.514+0300] {taskinstance.py:1398} INFO - Marking task as UP_FOR_RETRY. dag_id=dm1trybu, task_id=train_rf, execution_date=20231021T094500, start_date=20231022T185900, end_date=20231022T185950
[2023-10-22T21:59:50.522+0300] {standard_task_runner.py:104} ERROR - Failed to execute job 144 for task train_rf (Path 'rf' already exists and is not empty; 226091)
[2023-10-22T21:59:50.545+0300] {local_task_job_runner.py:228} INFO - Task exited with return code 1
[2023-10-22T21:59:50.565+0300] {taskinstance.py:2776} INFO - 0 downstream tasks scheduled from follow-on schedule check
