[2023-10-22T22:06:57.601+0300] {taskinstance.py:1157} INFO - Dependencies all met for dep_context=non-requeueable deps ti=<TaskInstance: dm1trybu.save_results scheduled__2023-10-21T09:45:00+00:00 [queued]>
[2023-10-22T22:06:57.606+0300] {taskinstance.py:1157} INFO - Dependencies all met for dep_context=requeueable deps ti=<TaskInstance: dm1trybu.save_results scheduled__2023-10-21T09:45:00+00:00 [queued]>
[2023-10-22T22:06:57.606+0300] {taskinstance.py:1359} INFO - Starting attempt 2 of 5
[2023-10-22T22:06:57.616+0300] {taskinstance.py:1380} INFO - Executing <Task(PythonOperator): save_results> on 2023-10-21 09:45:00+00:00
[2023-10-22T22:06:57.619+0300] {standard_task_runner.py:57} INFO - Started process 228590 to run task
[2023-10-22T22:06:57.622+0300] {standard_task_runner.py:84} INFO - Running: ['airflow', 'tasks', 'run', 'dm1trybu', 'save_results', 'scheduled__2023-10-21T09:45:00+00:00', '--job-id', '158', '--raw', '--subdir', 'DAGS_FOLDER/final_dag_3_models.py', '--cfg-path', '/tmp/tmpsrqk5tgh']
[2023-10-22T22:06:57.624+0300] {standard_task_runner.py:85} INFO - Job 158: Subtask save_results
[2023-10-22T22:06:57.673+0300] {task_command.py:415} INFO - Running <TaskInstance: dm1trybu.save_results scheduled__2023-10-21T09:45:00+00:00 [running]> on host dsbulgako1-QEMU-Virtual-Machine
[2023-10-22T22:06:57.747+0300] {taskinstance.py:1660} INFO - Exporting env vars: AIRFLOW_CTX_DAG_EMAIL='dmitrii.bulghakov@bk.ru' AIRFLOW_CTX_DAG_OWNER='Dmitry Bulgakov' AIRFLOW_CTX_DAG_ID='dm1trybu' AIRFLOW_CTX_TASK_ID='save_results' AIRFLOW_CTX_EXECUTION_DATE='2023-10-21T09:45:00+00:00' AIRFLOW_CTX_TRY_NUMBER='2' AIRFLOW_CTX_DAG_RUN_ID='scheduled__2023-10-21T09:45:00+00:00'
[2023-10-22T22:06:57.758+0300] {final_dag_3_models.py:259} INFO - Connecting to S3...
[2023-10-22T22:06:57.761+0300] {base_aws.py:553} WARNING - Unable to find AWS Connection ID 's3_connection', switching to empty.
[2023-10-22T22:06:57.761+0300] {base_aws.py:161} INFO - No connection ID provided. Fallback on boto3 credential strategy (region_name='ru-central1'). See: https://boto3.amazonaws.com/v1/documentation/api/latest/guide/configuration.html
[2023-10-22T22:06:57.784+0300] {credentials.py:1254} INFO - Found credentials in shared credentials file: ~/.aws/credentials
[2023-10-22T22:06:57.954+0300] {configprovider.py:949} INFO - Found endpoint for s3 via: config_global.
[2023-10-22T22:06:58.205+0300] {final_dag_3_models.py:266} INFO - Meta data uploaded to S3 successfully!
[2023-10-22T22:06:58.206+0300] {final_dag_3_models.py:267} INFO - Pipeline is finished!
[2023-10-22T22:06:58.206+0300] {python.py:194} INFO - Done. Returned value was: None
[2023-10-22T22:06:58.226+0300] {taskinstance.py:1398} INFO - Marking task as SUCCESS. dag_id=dm1trybu, task_id=save_results, execution_date=20231021T094500, start_date=20231022T190657, end_date=20231022T190658
[2023-10-22T22:06:58.240+0300] {local_task_job_runner.py:228} INFO - Task exited with return code 0
[2023-10-22T22:06:58.253+0300] {taskinstance.py:2776} INFO - 0 downstream tasks scheduled from follow-on schedule check
