[2023-10-22T20:47:58.947+0300] {taskinstance.py:1157} INFO - Dependencies all met for dep_context=non-requeueable deps ti=<TaskInstance: dm1trybu.get_data_from_postgres scheduled__2023-10-21T09:45:00+00:00 [queued]>
[2023-10-22T20:47:58.951+0300] {taskinstance.py:1157} INFO - Dependencies all met for dep_context=requeueable deps ti=<TaskInstance: dm1trybu.get_data_from_postgres scheduled__2023-10-21T09:45:00+00:00 [queued]>
[2023-10-22T20:47:58.951+0300] {taskinstance.py:1359} INFO - Starting attempt 3 of 4
[2023-10-22T20:47:58.956+0300] {taskinstance.py:1380} INFO - Executing <Task(PythonOperator): get_data_from_postgres> on 2023-10-21 09:45:00+00:00
[2023-10-22T20:47:58.960+0300] {standard_task_runner.py:57} INFO - Started process 212668 to run task
[2023-10-22T20:47:58.962+0300] {standard_task_runner.py:84} INFO - Running: ['airflow', 'tasks', 'run', 'dm1trybu', 'get_data_from_postgres', 'scheduled__2023-10-21T09:45:00+00:00', '--job-id', '106', '--raw', '--subdir', 'DAGS_FOLDER/final_dag_3_models.py', '--cfg-path', '/tmp/tmphxf5ofsd']
[2023-10-22T20:47:58.964+0300] {standard_task_runner.py:85} INFO - Job 106: Subtask get_data_from_postgres
[2023-10-22T20:47:59.005+0300] {task_command.py:415} INFO - Running <TaskInstance: dm1trybu.get_data_from_postgres scheduled__2023-10-21T09:45:00+00:00 [running]> on host dsbulgako1-QEMU-Virtual-Machine
[2023-10-22T20:47:59.064+0300] {taskinstance.py:1660} INFO - Exporting env vars: AIRFLOW_CTX_DAG_EMAIL='dmitrii.bulghakov@bk.ru' AIRFLOW_CTX_DAG_OWNER='Dmitry Bulgakov' AIRFLOW_CTX_DAG_ID='dm1trybu' AIRFLOW_CTX_TASK_ID='get_data_from_postgres' AIRFLOW_CTX_EXECUTION_DATE='2023-10-21T09:45:00+00:00' AIRFLOW_CTX_TRY_NUMBER='3' AIRFLOW_CTX_DAG_RUN_ID='scheduled__2023-10-21T09:45:00+00:00'
[2023-10-22T20:47:59.076+0300] {final_dag_3_models.py:116} INFO - Connecting to Postgres...
[2023-10-22T20:47:59.086+0300] {base.py:73} INFO - Using connection ID 'pg_connection' for task execution.
[2023-10-22T20:47:59.093+0300] {final_dag_3_models.py:121} INFO - Data downloading from Postgres...
[2023-10-22T20:47:59.095+0300] {logging_mixin.py:151} WARNING - /home/dsbulgako1/my_repos/mlops_project/dags/final_dag_3_models.py:122 UserWarning: pandas only supports SQLAlchemy connectable (engine/connection) or database string URI or sqlite3 DBAPI2 connection. Other DBAPI2 objects are not tested. Please consider using SQLAlchemy.
[2023-10-22T20:47:59.159+0300] {final_dag_3_models.py:126} INFO - Connecting to S3...
[2023-10-22T20:47:59.169+0300] {base_aws.py:553} WARNING - Unable to find AWS Connection ID 's3_connection', switching to empty.
[2023-10-22T20:47:59.170+0300] {base_aws.py:161} INFO - No connection ID provided. Fallback on boto3 credential strategy (region_name='ru-central1'). See: https://boto3.amazonaws.com/v1/documentation/api/latest/guide/configuration.html
[2023-10-22T20:47:59.293+0300] {credentials.py:1254} INFO - Found credentials in shared credentials file: ~/.aws/credentials
[2023-10-22T20:48:06.185+0300] {taskinstance.py:1935} ERROR - Task failed with exception
Traceback (most recent call last):
  File "/home/dsbulgako1/my_repos/mlops_project/env/lib/python3.10/site-packages/urllib3/connection.py", line 174, in _new_conn
    conn = connection.create_connection(
  File "/home/dsbulgako1/my_repos/mlops_project/env/lib/python3.10/site-packages/urllib3/util/connection.py", line 72, in create_connection
    for res in socket.getaddrinfo(host, port, family, socket.SOCK_STREAM):
  File "/usr/lib/python3.10/socket.py", line 955, in getaddrinfo
    for res in _socket.getaddrinfo(host, port, family, type, proto, flags):
socket.gaierror: [Errno -2] Name or service not known

During handling of the above exception, another exception occurred:

Traceback (most recent call last):
  File "/home/dsbulgako1/my_repos/mlops_project/env/lib/python3.10/site-packages/botocore/httpsession.py", line 465, in send
    urllib_response = conn.urlopen(
  File "/home/dsbulgako1/my_repos/mlops_project/env/lib/python3.10/site-packages/urllib3/connectionpool.py", line 798, in urlopen
    retries = retries.increment(
  File "/home/dsbulgako1/my_repos/mlops_project/env/lib/python3.10/site-packages/urllib3/util/retry.py", line 525, in increment
    raise six.reraise(type(error), error, _stacktrace)
  File "/home/dsbulgako1/my_repos/mlops_project/env/lib/python3.10/site-packages/urllib3/packages/six.py", line 770, in reraise
    raise value
  File "/home/dsbulgako1/my_repos/mlops_project/env/lib/python3.10/site-packages/urllib3/connectionpool.py", line 714, in urlopen
    httplib_response = self._make_request(
  File "/home/dsbulgako1/my_repos/mlops_project/env/lib/python3.10/site-packages/urllib3/connectionpool.py", line 403, in _make_request
    self._validate_conn(conn)
  File "/home/dsbulgako1/my_repos/mlops_project/env/lib/python3.10/site-packages/urllib3/connectionpool.py", line 1053, in _validate_conn
    conn.connect()
  File "/home/dsbulgako1/my_repos/mlops_project/env/lib/python3.10/site-packages/urllib3/connection.py", line 363, in connect
    self.sock = conn = self._new_conn()
  File "/home/dsbulgako1/my_repos/mlops_project/env/lib/python3.10/site-packages/urllib3/connection.py", line 186, in _new_conn
    raise NewConnectionError(
urllib3.exceptions.NewConnectionError: <botocore.awsrequest.AWSHTTPSConnection object at 0xffff989fe890>: Failed to establish a new connection: [Errno -2] Name or service not known

During handling of the above exception, another exception occurred:

Traceback (most recent call last):
  File "/home/dsbulgako1/my_repos/mlops_project/env/lib/python3.10/site-packages/airflow/operators/python.py", line 192, in execute
    return_value = self.execute_callable()
  File "/home/dsbulgako1/my_repos/mlops_project/env/lib/python3.10/site-packages/airflow/operators/python.py", line 209, in execute_callable
    return self.python_callable(*self.op_args, **self.op_kwargs)
  File "/home/dsbulgako1/my_repos/mlops_project/dags/final_dag_3_models.py", line 131, in get_data_from_postgres
    resource.Object(BUCKET, file_name).put(Body=pickle_byte_obj)
  File "/home/dsbulgako1/my_repos/mlops_project/env/lib/python3.10/site-packages/boto3/resources/factory.py", line 580, in do_action
    response = action(self, *args, **kwargs)
  File "/home/dsbulgako1/my_repos/mlops_project/env/lib/python3.10/site-packages/boto3/resources/action.py", line 88, in __call__
    response = getattr(parent.meta.client, operation_name)(*args, **params)
  File "/home/dsbulgako1/my_repos/mlops_project/env/lib/python3.10/site-packages/botocore/client.py", line 535, in _api_call
    return self._make_api_call(operation_name, kwargs)
  File "/home/dsbulgako1/my_repos/mlops_project/env/lib/python3.10/site-packages/botocore/client.py", line 963, in _make_api_call
    http, parsed_response = self._make_request(
  File "/home/dsbulgako1/my_repos/mlops_project/env/lib/python3.10/site-packages/botocore/client.py", line 986, in _make_request
    return self._endpoint.make_request(operation_model, request_dict)
  File "/home/dsbulgako1/my_repos/mlops_project/env/lib/python3.10/site-packages/botocore/endpoint.py", line 119, in make_request
    return self._send_request(request_dict, operation_model)
  File "/home/dsbulgako1/my_repos/mlops_project/env/lib/python3.10/site-packages/botocore/endpoint.py", line 202, in _send_request
    while self._needs_retry(
  File "/home/dsbulgako1/my_repos/mlops_project/env/lib/python3.10/site-packages/botocore/endpoint.py", line 354, in _needs_retry
    responses = self._event_emitter.emit(
  File "/home/dsbulgako1/my_repos/mlops_project/env/lib/python3.10/site-packages/botocore/hooks.py", line 412, in emit
    return self._emitter.emit(aliased_event_name, **kwargs)
  File "/home/dsbulgako1/my_repos/mlops_project/env/lib/python3.10/site-packages/botocore/hooks.py", line 256, in emit
    return self._emit(event_name, kwargs)
  File "/home/dsbulgako1/my_repos/mlops_project/env/lib/python3.10/site-packages/botocore/hooks.py", line 239, in _emit
    response = handler(**kwargs)
  File "/home/dsbulgako1/my_repos/mlops_project/env/lib/python3.10/site-packages/botocore/retryhandler.py", line 207, in __call__
    if self._checker(**checker_kwargs):
  File "/home/dsbulgako1/my_repos/mlops_project/env/lib/python3.10/site-packages/botocore/retryhandler.py", line 284, in __call__
    should_retry = self._should_retry(
  File "/home/dsbulgako1/my_repos/mlops_project/env/lib/python3.10/site-packages/botocore/retryhandler.py", line 320, in _should_retry
    return self._checker(attempt_number, response, caught_exception)
  File "/home/dsbulgako1/my_repos/mlops_project/env/lib/python3.10/site-packages/botocore/retryhandler.py", line 363, in __call__
    checker_response = checker(
  File "/home/dsbulgako1/my_repos/mlops_project/env/lib/python3.10/site-packages/botocore/retryhandler.py", line 247, in __call__
    return self._check_caught_exception(
  File "/home/dsbulgako1/my_repos/mlops_project/env/lib/python3.10/site-packages/botocore/retryhandler.py", line 416, in _check_caught_exception
    raise caught_exception
  File "/home/dsbulgako1/my_repos/mlops_project/env/lib/python3.10/site-packages/botocore/endpoint.py", line 281, in _do_get_response
    http_response = self._send(request)
  File "/home/dsbulgako1/my_repos/mlops_project/env/lib/python3.10/site-packages/botocore/endpoint.py", line 377, in _send
    return self.http_session.send(request)
  File "/home/dsbulgako1/my_repos/mlops_project/env/lib/python3.10/site-packages/botocore/httpsession.py", line 494, in send
    raise EndpointConnectionError(endpoint_url=request.url, error=e)
botocore.exceptions.EndpointConnectionError: Could not connect to the endpoint URL: "https://mlops-project.s3.ru-central1.amazonaws.com/dm1trybu/datasets/california_housing.pkl"
[2023-10-22T20:48:06.197+0300] {taskinstance.py:1398} INFO - Marking task as UP_FOR_RETRY. dag_id=dm1trybu, task_id=get_data_from_postgres, execution_date=20231021T094500, start_date=20231022T174758, end_date=20231022T174806
[2023-10-22T20:48:06.203+0300] {standard_task_runner.py:104} ERROR - Failed to execute job 106 for task get_data_from_postgres (Could not connect to the endpoint URL: "https://mlops-project.s3.ru-central1.amazonaws.com/dm1trybu/datasets/california_housing.pkl"; 212668)
[2023-10-22T20:48:06.225+0300] {local_task_job_runner.py:228} INFO - Task exited with return code 1
[2023-10-22T20:48:06.242+0300] {taskinstance.py:2776} INFO - 0 downstream tasks scheduled from follow-on schedule check
