[2023-10-22T21:18:30.624+0300] {taskinstance.py:1157} INFO - Dependencies all met for dep_context=non-requeueable deps ti=<TaskInstance: dm1trybu.init scheduled__2023-10-21T09:45:00+00:00 [queued]>
[2023-10-22T21:18:30.628+0300] {taskinstance.py:1157} INFO - Dependencies all met for dep_context=requeueable deps ti=<TaskInstance: dm1trybu.init scheduled__2023-10-21T09:45:00+00:00 [queued]>
[2023-10-22T21:18:30.628+0300] {taskinstance.py:1359} INFO - Starting attempt 22 of 24
[2023-10-22T21:18:30.634+0300] {taskinstance.py:1380} INFO - Executing <Task(PythonOperator): init> on 2023-10-21 09:45:00+00:00
[2023-10-22T21:18:30.637+0300] {standard_task_runner.py:57} INFO - Started process 219508 to run task
[2023-10-22T21:18:30.641+0300] {standard_task_runner.py:84} INFO - Running: ['airflow', 'tasks', 'run', 'dm1trybu', 'init', 'scheduled__2023-10-21T09:45:00+00:00', '--job-id', '138', '--raw', '--subdir', 'DAGS_FOLDER/final_dag_3_models.py', '--cfg-path', '/tmp/tmphgbvsp23']
[2023-10-22T21:18:30.642+0300] {standard_task_runner.py:85} INFO - Job 138: Subtask init
[2023-10-22T21:18:30.684+0300] {task_command.py:415} INFO - Running <TaskInstance: dm1trybu.init scheduled__2023-10-21T09:45:00+00:00 [running]> on host dsbulgako1-QEMU-Virtual-Machine
[2023-10-22T21:18:30.744+0300] {taskinstance.py:1660} INFO - Exporting env vars: AIRFLOW_CTX_DAG_EMAIL='dmitrii.bulghakov@bk.ru' AIRFLOW_CTX_DAG_OWNER='Dmitry Bulgakov' AIRFLOW_CTX_DAG_ID='dm1trybu' AIRFLOW_CTX_TASK_ID='init' AIRFLOW_CTX_EXECUTION_DATE='2023-10-21T09:45:00+00:00' AIRFLOW_CTX_TRY_NUMBER='22' AIRFLOW_CTX_DAG_RUN_ID='scheduled__2023-10-21T09:45:00+00:00'
[2023-10-22T21:18:30.745+0300] {final_dag_3_models.py:72} INFO - Initializing dag and collecting meta-data...
[2023-10-22T21:18:30.745+0300] {final_dag_3_models.py:82} INFO - Trying to set new experiment...
[2023-10-22T21:18:30.930+0300] {migration.py:213} INFO - Context impl PostgresqlImpl.
[2023-10-22T21:18:30.930+0300] {migration.py:216} INFO - Will assume transactional DDL.
[2023-10-22T21:18:30.944+0300] {final_dag_3_models.py:92} INFO - Experiment 'dm1trybu' already exists in MLFlow.
[2023-10-22T21:18:30.946+0300] {taskinstance.py:1935} ERROR - Task failed with exception
Traceback (most recent call last):
  File "/home/dsbulgako1/my_repos/mlops_project/env/lib/python3.10/site-packages/airflow/operators/python.py", line 192, in execute
    return_value = self.execute_callable()
  File "/home/dsbulgako1/my_repos/mlops_project/env/lib/python3.10/site-packages/airflow/operators/python.py", line 209, in execute_callable
    return self.python_callable(*self.op_args, **self.op_kwargs)
  File "/home/dsbulgako1/my_repos/mlops_project/dags/final_dag_3_models.py", line 95, in init
    mlflow.set_experiment(metrics["experiment_name"])
  File "/home/dsbulgako1/my_repos/mlops_project/env/lib/python3.10/site-packages/mlflow/tracking/fluent.py", line 148, in set_experiment
    raise MlflowException(
mlflow.exceptions.MlflowException: Cannot set a deleted experiment 'dm1trybu' as the active experiment. You can restore the experiment, or permanently delete the experiment to create a new one.
[2023-10-22T21:18:30.956+0300] {taskinstance.py:1398} INFO - Marking task as UP_FOR_RETRY. dag_id=dm1trybu, task_id=init, execution_date=20231021T094500, start_date=20231022T181830, end_date=20231022T181830
[2023-10-22T21:18:30.962+0300] {standard_task_runner.py:104} ERROR - Failed to execute job 138 for task init (Cannot set a deleted experiment 'dm1trybu' as the active experiment. You can restore the experiment, or permanently delete the experiment to create a new one.; 219508)
[2023-10-22T21:18:30.972+0300] {local_task_job_runner.py:228} INFO - Task exited with return code 1
[2023-10-22T21:18:30.990+0300] {taskinstance.py:2776} INFO - 0 downstream tasks scheduled from follow-on schedule check
